Workbook

Sheet Leia primeiro
A1: AUMI | Portfólio: loja LATAM + mapa de TI
A4: PROPOSTA EM 02/10/2026 — Nichos ainda serão escolhidos por validação. Não há catálogo ou pipeline comprovado. Esta planilha não inclui a oferta Topologic empresarial de R$200 mil + R$12 mil/mês.
A6: Como usar: leia Resumo e Capital; examine Economia e Escala; edite células azuis em Premissas e agendas de pedidos/mapas nas três abas mensais. Fórmulas têm resultados em cache para leitura sem Excel; após editar, abra em aplicativo com recálculo de fórmulas.
A8: Unidade: BRL salvo indicação USD, pedidos, visitas, horas ou mês. Receita após estornos não é caixa. Loja recebe líquido da plataforma em M+1. Mapa recebe 50% no mês e 50% no seguinte. Tributos provisionados no mês da venda/fatura; comercial TI sobre caixa recebido.
A10: Capital exigido = pico do déficit acumulado incluindo M0 + três meses de fixo do ano 2, arredondado para cima em R$10 mil. Caixa acumulado exclui aportes, juros e dividendos. Os cenários pressupõem financiamento completo, sem interrupção por insolvência.
A12: Sociedade confirmada: Dani 50%; AUMI 50% conjunto (Marcos, Luciana e João; divisão interna indefinida). Aporte, cargos, remunerações, política de distribuição e instrumento societário não acordados.
A14: Dani: exemplo exclusivamente hipotético de financiadora única de todo capital requerido; 50% do excedente acumulado positivo do projeto. Não é dividendo automaticamente disponível, nem payout acordado. Sem tributos pessoais e sem reinvestimento. Não somar excedentes acumulados de meses diferentes.
A16: Sensibilidades CAC15 e FX4,5 usam exatamente as agendas do cenário Base. Custos, tributos, câmbio, preços, conversão e prazos são hipóteses. Taxa Hotmart: tabela/FAQ USD >15, 9,9% + USD1, efetiva em 21/09/2026; confirmar condições da conta.
A18: Volume operacional importa: todas as vendas suportam CAC, inclusive as que seriam orgânicas. Visitas usam conversão hipotética de 2%. Horas TI são horas diretas de entrega, além da equipe fixa. Escala é estado estacionário, não fluxo de lançamento.
A20: Navegação: Premissas → Economia → Conservador/Base/Escala24 → Resumo → Capital → Escala → CAC15/FX4,5 → Gates → Fontes. Dados e séries: pitch-data.json, revisão 2026-10-02.

Sheet Premissas
A1: Premissas editáveis | azul = entrada
A4: Premissa | B4: Valor | C4: Unidade / status | D4: Significado e limites
A5: Ticket loja | B5: 29 | C5: USD/pedido | D5: Preço hipotético antes dos tributos do comprador
A6: Câmbio | B6: 5 | C6: BRL/USD | D6: Hipótese; não é cotação
A7: Estornos | B7: 0.08 | C7: % bruto | D7: Estornos sobre pedidos aprovados
A8: Plataforma variável | B8: 0.099 | C8: % após estorno | D8: Hotmart tabela/FAQ; não sobre pedidos reembolsados
A9: Plataforma fixa | B9: 1 | C9: USD não reembolsado | D9: USD1 efetivo 21/09/2026; confirmar condições da conta
A10: Provisão tributária | B10: 0.15 | C10: % após estorno / fatura TI | D10: 15% novo portfólio; não 12% do modelo antigo. Confirmar regime.
A11: Meios / câmbio | B11: 0.03 | C11: % após estorno | D11: Reserva adicional hipotética; não tarifa citada
A12: Aquisição / CAC | B12: 10 | C12: USD/pedido aprovado | D12: Inclui todos os pedidos, inclusive reembolsados
A13: Suporte loja | B13: 1 | C13: USD/pedido aprovado | D13: Custo variável, sem duplicar equipe fixa
A14: Conversão em pedidos | B14: 0.02 | C14: % visitas qualificadas | D14: Hipótese, não medição
A15: Preço mapa TI | B15: 30000 | C15: BRL/projeto | D15: Oferta proposta; escopo limitado, validar com comprador
A16: Horas diretas mapa | B16: 80 | C16: horas/projeto | D16: 80h diretas, além de P&D fixo
... A22: Pré-operação M0 | B22: 24000 | C22: BRL | D22: Jurídico12k + segurança12k; provisões
A23: Investimento M0 | B23: ='Premissas'!$B$21+'Premissas'!$B$22 -> 100000 | C23: BRL calculado | D23: Infraestrutura + pré-operação; sem autorização de compra
A24: Fixo mensal ano 1 | B24: 37000 | C24: BRL/mês | D24: Envelopes operacionais, não salários pesquisados
A25: Fixo mensal ano 2 | B25: 42000 | C25: BRL/mês | D25: Hipótese de ampliação da equipe/custos
A26: Reserva de segurança | B26: 3 | C26: meses de fixo ano 2 | D26: Além do pico de déficit
A27: Arredondamento capital | B27: 10000 | C27: BRL | D27: Arredondar para cima em múltiplos deste valor
A28: Participação Dani | B28: 0.5 | C28: % | D28: 50% confirmado; payout não acordado
A29: CAC sensibilizado | B29: 15 | C29: USD/pedido | D29: Apenas sensibilidade, mesma agenda Base
A30: Câmbio sensibilizado | B30: 4.5 | C30: BRL/USD | D30: Apenas sensibilidade, mesma agenda Base

Sheet Economia
A1: Economia unitária | contribuição não é lucro
A4: Loja por pedido aprovado | B4: USD | C4: BRL | D4: Base de incidência | E4: Status
A5: Venda bruta | B5: ='Premissas'!$B$5 -> 29 | C5: =B5*'Premissas'!$B$6 -> 145 | D5: Pedido aprovado | E5: Hipótese / fonte em Fontes
A6: Estornos | B6: =B5*'Premissas'!$B$7 -> 2.32 | C6: =B6*'Premissas'!$B$6 -> 11.6 | D6: 8% bruto | E6: Hipótese / fonte em Fontes
A7: Receita após estorno | B7: =B5-B6 -> 26.68 | C7: =B7*'Premissas'!$B$6 -> 133.4 | D7: Receita reconhecida | E7: Hipótese / fonte em Fontes
A8: Plataforma | B8: =B7*'Premissas'!$B$8+(1-'Premissas'!$B$7)*'Premissas'!$B$9 -> 3.56132 | C8: =B8*'Premissas'!$B$6 -> 17.8066 | D8: Somente concluídos sem estorno | E8: Hipótese / fonte em Fontes
A9: Tributos provisionados | B9: =B7*'Premissas'!$B$10 -> 4.002 | C9: =B9*'Premissas'!$B$6 -> 20.01 | D9: Após estorno | E9: Hipótese / fonte em Fontes
A10: Reserva meios/câmbio | B10: =B7*'Premissas'!$B$11 -> 0.8004 | C10: =B10*'Premissas'!$B$6 -> 4.002 | D10: Após estorno | E10: Hipótese / fonte em Fontes
A11: CAC | B11: ='Premissas'!$B$12 -> 10 | C11: =B11*'Premissas'!$B$6 -> 50 | D11: Todos os pedidos aprovados | E11: Hipótese / fonte em Fontes
A12: Suporte | B12: ='Premissas'!$B$13 -> 1 | C12: =B12*'Premissas'!$B$6 -> 5 | D12: Todos os pedidos aprovados | E12: Hipótese / fonte em Fontes
A13: Contribuição loja | B13: =B7-SUM(B8:B12) -> 7.31628 | C13: =B13*'Premissas'!$B$6 -> 36.5814 | D13: Antes de fixo / M0 | E13: Hipótese / fonte em Fontes
A16: Mapa de TI por projeto | B16: BRL | C16: Cálculo | D16: Escopo | E16: Status
A17: Preço | B17: ='Premissas'!$B$15 -> 30000
A18: Entrega direta | B18: ='Premissas'!$B$16*'Premissas'!$B$17 -> 14400
A19: Tributos | B19: =B17*'Premissas'!$B$10 -> 4500
A20: Comercial | B20: =B17*'Premissas'!$B$18 -> 1500
A21: Contribuição mapa | B21: =B17-SUM(B18:B20) -> 9600
A24: Pedidos/mês para cobrir fixo ano 2, sem mapas | B24: =ROUNDUP('Premissas'!$B$25/C13,0) -> 1149
A25: CAC que zera contribuição unitária (USD) | B25: =B13+'Premissas'!$B$12 -> 17.31628
A28: Unitário preserva 6 casas; nos fluxos mensais cada componente monetário é arredondado a 2 casas. Contribuição não inclui fixo, M0 ou capital de giro.

Sheet Conservador
A1: Conservador | fluxo mensal em BRL, salvo indicação
A2: Agenda editável em azul. Cenário hipotético; não previsão. | M0 separado: -R$100 mil nas premissas. Acumulado exclui aportes/distribuição.
A4: Mês | B4: Pedidos aprovados | C4: Visitas qualificadas | D4: Mapas faturados | E4: Horas diretas TI | F4: Loja bruta USD | G4: Loja bruta BRL | H4: Estornos BRL | I4: Loja após estornos BRL | J4: Taxa plataforma BRL | K4: Liquidação gerada BRL | L4: Loja recebida BRL | M4: Tributos loja BRL | N4: Reserva meios/FX BRL | O4: Aquisição / mídia BRL | P4: Suporte loja BRL | Q4: Fatura TI BRL | R4: Recebimentos TI BRL | S4: Entrega TI BRL | T4: Tributos TI BRL | U4: Comercial TI caixa BRL | V4: Fixo BRL | W4: Vendas brutas BRL | X4: Receita após estornos BRL | Y4: Recebimentos BRL | Z4: Saídas caixa BRL | AA4: Fluxo líquido BRL | AB4: Acumulado sem aporte BRL | AC4: Resultado competência BRL | AD4: A receber BRL | AE4: 50% excedente positivo BRL | AF4: Mês elegível payback projeto | AG4: Mês elegível Dani hipotético | AH4: Saldo com 100k | AI4: Saldo com 150k | AJ4: Saldo com 200k
A5: 1 | B5: 0 | C5: =ROUNDUP(B5/'Premissas'!$B$14,0) -> 0 | D5: 0 | E5: =D5*'Premissas'!$B$16 -> 0 | F5: =ROUND(B5*'Premissas'!$B$5,2) -> 0 | G5: =ROUND(F5*'Premissas'!$B$6,2) -> 0 | H5: =ROUND(G5*'Premissas'!$B$7,2) -> 0 | I5: =ROUND(G5-H5,2) -> 0 | J5: =ROUND(I5*'Premissas'!$B$8+B5*(1-'Premissas'!$B$7)*'Premissas'!$B$9*'Premissas'!$B$6,2) -> 0 | K5: =ROUND(I5-J5,2) -> 0 | L5: =IF(A5>'Premissas'!$B$20,INDEX($K$5:$K$28,MAX(1,A5-'Premissas'!$B$20)),0) -> 0 | M5: =ROUND(I5*'Premissas'!$B$10,2) -> 0 | N5: =ROUND(I5*'Premissas'!$B$11,2) -> 0 | O5: =ROUND(B5*'Premissas'!$B$12*'Premissas'!$B$6,2) -> 0 | P5: =ROUND(B5*'Premissas'!$B$13*'Premissas'!$B$6,2) -> 0 | Q5: =ROUND(D5*'Premissas'!$B$15,2) -> 0 | R5: =ROUND(Q5*'Premissas'!$B$19+0*(1-'Premissas'!$B$19),2) -> 0 | S5: =ROUND(E5*'Premissas'!$B$17,2) -> 0 | T5: =ROUND(Q5*'Premissas'!$B$10,2) -> 0 | U5: =ROUND(R5*'Premissas'!$B$18,2) -> 0 | V5: =IF(A5<=12,'Premissas'!$B$24,'Premissas'!$B$25) -> 37000 | W5: =ROUND(G5+Q5,2) -> 0 | X5: =ROUND(I5+Q5,2) -> 0 | Y5: =ROUND(L5+R5,2) -> 0 | Z5: =ROUND(SUM(M5:P5)+SUM(S5:V5),2) -> 37000 | AA5: =ROUND(Y5-Z5,2) -> -37000 | AB5: =ROUND(-'Premissas'!$B$23+AA5,2) -> -137000 | AC5: =ROUND(X5-J5-SUM(M5:P5)-S5-T5-ROUND(Q5*'Premissas'!$B$18,2)-V5,2) -> -37000 | AD5: =ROUND(SUM($K$5:K5)-SUM($L$5:L5)+SUM($Q$5:Q5)-SUM($R$5:R5),2) -> 0 | AE5: =MAX(0,AB5)*'Premissas'!$B$28 -> 0 | AF5: =IF(AB5>=0,A5,999) -> 999 | AG5: =IF(AE5>=Resumo!$E$5,A5,999) -> 999 | AH5: =AB5+Capital!$A$5 -> -37000 | AI5: =AB5+Capital!$A$6 -> 13000 | AJ5: =AB5+Capital!$A$7 -> 63000
A6: 2 | B6: 0 | C6: =ROUNDUP(B6/'Premissas'!$B$14,0) -> 0 | D6: 0 | E6: =D6*'Premissas'!$B$16 -> 0 | F6: =ROUND(B6*'Premissas'!$B$5,2) -> 0 | G6: =ROUND(F6*'Premissas'!$B$6,2) -> 0 | H6: =ROUND(G6*'Premissas'!$B$7,2) -> 0 | I6: =ROUND(G6-H6,2) -> 0 | J6: =ROUND(I6*'Premissas'!$B$8+B6*(1-'Premissas'!$B$7)*'Premissas'!$B$9*'Premissas'!$B$6,2) -> 0 | K6: =ROUND(I6-J6,2) -> 0 | L6: =IF(A6>'Premissas'!$B$20,INDEX($K$5:$K$28,MAX(1,A6-'Premissas'!$B$20)),0) -> 0 | M6: =ROUND(I6*'Premissas'!$B$10,2) -> 0 | N6: =ROUND(I6*'Premissas'!$B$11,2) -> 0 | O6: =ROUND(B6*'Premissas'!$B$12*'Premissas'!$B$6,2) -> 0 | P6: =ROUND(B6*'Premissas'!$B$13*'Premissas'!$B$6,2) -> 0 | Q6: =ROUND(D6*'Premissas'!$B$15,2) -> 0 | R6: =ROUND(Q6*'Premissas'!$B$19+Q5*(1-'Premissas'!$B$19),2) -> 0 | S6: =ROUND(E6*'Premissas'!$B$17,2) -> 0 | T6: =ROUND(Q6*'Premissas'!$B$10,2) -> 0 | U6: =ROUND(R6*'Premissas'!$B$18,2) -> 0 | V6: =IF(A6<=12,'Premissas'!$B$24,'Premissas'!$B$25) -> 37000 | W6: =ROUND(G6+Q6,2) -> 0 | X6: =ROUND(I6+Q6,2) -> 0 | Y6: =ROUND(L6+R6,2) -> 0 | Z6: =ROUND(SUM(M6:P6)+SUM(S6:V6),2) -> 37000 | AA6: =ROUND(Y6-Z6,2) -> -37000 | AB6: =ROUND(AB5+AA6,2) -> -174000 | AC6: =ROUND(X6-J6-SUM(M6:P6)-S6-T6-ROUND(Q6*'Premissas'!$B$18,2)-V6,2) -> -37000 | AD6: =ROUND(SUM($K$5:K6)-SUM($L$5:L6)+SUM($Q$5:Q6)-SUM($R$5:R6),2) -> 0 | AE6: =MAX(0,AB6)*'Premissas'!$B$28 -> 0 | AF6: =IF(AB6>=0,A6,999) -> 999 | AG6: =IF(AE6>=Resumo!$E$5,A6,999) -> 999 | AH6: =AB6+Capital!$A$5 -> -74000 | AI6: =AB6+Capital!$A$6 -> -24000 | AJ6: =AB6+Capital!$A$7 -> 26000
A7: 3 | B7: 20 | C7: =ROUNDUP(B7/'Premissas'!$B$14,0) -> 1000 | D7: 0 | E7: =D7*'Premissas'!$B$16 -> 0 | F7: =ROUND(B7*'Premissas'!$B$5,2) -> 580 | G7: =ROUND(F7*'Premissas'!$B$6,2) -> 2900 | H7: =ROUND(G7*'Premissas'!$B$7,2) -> 232 | I7: =ROUND(G7-H7,2) -> 2668 | J7: =ROUND(I7*'Premissas'!$B$8+B7*(1-'Premissas'!$B$7)*'Premissas'!$B$9*'Premissas'!$B$6,2) -> 356.13 | K7: =ROUND(I7-J7,2) -> 2311.87 | L7: =IF(A7>'Premissas'!$B$20,INDEX($K$5:$K$28,MAX(1,A7-'Premissas'!$B$20)),0) -> 0 | M7: =ROUND(I7*'Premissas'!$B$10,2) -> 400.2 | N7: =ROUND(I7*'Premissas'!$B$11,2) -> 80.04 | O7: =ROUND(B7*'Premissas'!$B$12*'Premissas'!$B$6,2) -> 1000 | P7: =ROUND(B7*'Premissas'!$B$13*'Premissas'!$B$6,2) -> 100 | Q7: =ROUND(D7*'Premissas'!$B$15,2) -> 0 | R7: =ROUND(Q7*'Premissas'!$B$19+Q6*(1-'Premissas'!$B$19),2) -> 0 | S7: =ROUND(E7*'Premissas'!$B$17,2) -> 0 | T7: =ROUND(Q7*'Premissas'!$B$10,2) -> 0 | U7: =ROUND(R7*'Premissas'!$B$18,2) -> 0 | V7: =IF(A7<=12,'Premissas'!$B$24,'Premissas'!$B$25) -> 37000 | W7: =ROUND(G7+Q7,2) -> 2900 | X7: =ROUND(I7+Q7,2) -> 2668 | Y7: =ROUND(L7+R7,2) -> 0 | Z7: =ROUND(SUM(M7:P7)+SUM(S7:V7),2) -> 38580.24 | AA7: =ROUND(Y7-Z7,2) -> -38580.24 | AB7: =ROUND(AB6+AA7,2) -> -212580.24 | AC7: =ROUND(X7-J7-SUM(M7:P7)-S7-T7-ROUND(Q7*'Premissas'!$B$18,2)-V7,2) -> -36268.37 | AD7: =ROUND(SUM($K$5:K7)-SUM($L$5:L7)+SUM($Q$5:Q7)-SUM($R$5:R7),2) -> 2311.87 | AE7: =MAX(0,AB7)*'Premissas'!$B$28 -> 0 | AF7: =IF(AB7>=0,A7,999) -> 999 | AG7: =IF(AE7>=Resumo!$E$5,A7,999) -> 999 | AH7: =AB7+Capital!$A$5 -> -112580.24 | AI7: =AB7+Capital!$A$6 -> -62580.24 | AJ7: =AB7+Capital!$A$7 -> -12580.24
A8: 4 | B8: 40 | C8: =ROUNDUP(B8/'Premissas'!$B$14,0) -> 2000 | D8: 0 | E8: =D8*'Premissas'!$B$16 -> 0 | F8: =ROUND(B8*'Premissas'!$B$5,2) -> 1160 | G8: =ROUND(F8*'Premissas'!$B$6,2) -> 5800 | H8: =ROUND(G8*'Premissas'!$B$7,2) -> 464 | I8: =ROUND(G8-H8,2) -> 5336 | J8: =ROUND(I8*'Premissas'!$B$8+B8*(1-'Premissas'!$B$7)*'Premissas'!$B$9*'Premissas'!$B$6,2) -> 712.26 | K8: =ROUND(I8-J8,2) -> 4623.74 | L8: =IF(A8>'Premissas'!$B$20,INDEX($K$5:$K$28,MAX(1,A8-'Premissas'!$B$20)),0) -> 2311.87 | M8: =ROUND(I8*'Premissas'!$B$10,2) -> 800.4 | N8: =ROUND(I8*'Premissas'!$B$11,2) -> 160.08 | O8: =ROUND(B8*'Premissas'!$B$12*'Premissas'!$B$6,2) -> 2000 | P8: =ROUND(B8*'Premissas'!$B$13*'Premissas'!$B$6,2) -> 200 | Q8: =ROUND(D8*'Premissas'!$B$15,2) -> 0 | R8: =ROUND(Q8*'Premissas'!$B$19+Q7*(1-'Premissas'!$B$19),2) -> 0 | S8: =ROUND(E8*'Premissas'!$B$17,2) -> 0 | T8: =ROUND(Q8*'Premissas'!$B$10,2) -> 0 | U8: =ROUND(R8*'Premissas'!$B$18,2) -> 0 | V8: =IF(A8<=12,'Premissas'!$B$24,'Premissas'!$B$25) -> 37000 | W8: =ROUND(G8+Q8,2) -> 5800 | X8: =ROUND(I8+Q8,2) -> 5336 | Y8: =ROUND(L8+R8,2) -> 2311.87 | Z8: =ROUND(SUM(M8:P8)+SUM(S8:V8),2) -> 40160.48 | AA8: =ROUND(Y8-Z8,2) -> -37848.61 | AB8: =ROUND(AB7+AA8,2) -> -250428.85 | AC8: =ROUND(X8-J8-SUM(M8:P8)-S8-T8-ROUND(Q8*'Premissas'!$B$18,2)-V8,2) -> -35536.74 | AD8: =ROUND(SUM($K$5:K8)-SUM($L$5:L8)+SUM($Q$5:Q8)-SUM($R$5:R8),2) -> 4623.74 | AE8: =MAX(0,AB8)*'Premissas'!$B$28 -> 0 | AF8: =IF(AB8>=0,A8,999) -> 999 | AG8: =IF(AE8>=Resumo!$E$5,A8,999) -> 999 | AH8: =AB8+Capital!$A$5 -> -150428.85 | AI8: =AB8+Capital!$A$6 -> -100428.85 | AJ8: =AB8+Capital!$A$7 -> -50428.85
A9: 5 | B9: 80 | C9: =ROUNDUP(B9/'Premissas'!$B$14,0) -> 4000 | D9: 1 | E9: =D9*'Premissas'!$B$16 -> 80 | F9: =ROUND(B9*'Premissas'!$B$5,2) -> 2320 | G9: =ROUND(F9*'Premissas'!$B$6,2) -> 11600 | H9: =ROUND(G9*'Premissas'!$B$7,2) -> 928 | I9: =ROUND(G9-H9,2) -> 10672 | J9: =ROUND(I9*'Premissas'!$B$8+B9*(1-'Premissas'!$B$7)*'Premissas'!$B$9*'Premissas'!$B$6,2) -> 1424.53 | K9: =ROUND(I9-J9,2) -> 9247.47 | L9: =IF(A9>'Premissas'!$B$20,INDEX($K$5:$K$28,MAX(1,A9-'Premissas'!$B$20)),0) -> 4623.74 | M9: =ROUND(I9*'Premissas'!$B$10,2) -> 1600.8 | N9: =ROUND(I9*'Premissas'!$B$11,2) -> 320.16 | O9: =ROUND(B9*'Premissas'!$B$12*'Premissas'!$B$6,2) -> 4000 | P9: =ROUND(B9*'Premissas'!$B$13*'Premissas'!$B$6,2) -> 400 | Q9: =ROUND(D9*'Premissas'!$B$15,2) -> 30000 | R9: =ROUND(Q9*'Premissas'!$B$19+Q8*(1-'Premissas'!$B$19),2) -> 15000 | S9: =ROUND(E9*'Premissas'!$B$17,2) -> 14400 | T9: =ROUND(Q9*'Premissas'!$B$10,2) -> 4500 | U9: =ROUND(R9*'Premissas'!$B$18,2) -> 750 | V9: =IF(A9<=12,'Premissas'!$B$24,'Premissas'!$B$25) -> 37000 | W9: =ROUND(G9+Q9,2) -> 41600 | X9: =ROUND(I9+Q9,2) -> 40672 | Y9: =ROUND(L9+R9,2) -> 19623.74 | Z9: =ROUND(SUM(M9:P9)+SUM(S9:V9),2) -> 62970.96 | AA9: =ROUND(Y9-Z9,2) -> -43347.22 | AB9: =ROUND(AB8+AA9,2) -> -293776.07 | AC9: =ROUND(X9-J9-SUM(M9:P9)-S9-T9-ROUND(Q9*'Premissas'!$B$18,2)-V9,2) -> -24473.49 | AD9: =ROUND(SUM($K$5:K9)-SUM($L$5:L9)+SUM($Q$5:Q9)-SUM($R$5:R9),2) -> 24247.47 | AE9: =MAX(0,AB9)*'Premissas'!$B$28 -> 0 | AF9: =IF(AB9>=0,A9,999) -> 999 | AG9: =IF(AE9>=Resumo!$E$5,A9,999) -> 999 | AH9: =AB9+Capital!$A$5 -> -193776.07 | AI9: =AB9+Capital!$A$6 -> -143776.07 | AJ9: =AB9+Capital!$A$7 -> -93776.07
A10: 6 | B10: 120 | C10: =ROUNDUP(B10/'Premissas'!$B$14,0) -> 6000 | D10: 0 | E10: =D10*'Premissas'!$B$16 -> 0 | F10: =ROUND(B10*'Premissas'!$B$5,2) -> 3480 | G10: =ROUND(F10*'Premissas'!$B$6,2) -> 17400 | H10: =ROUND(G10*'Premissas'!$B$7,2) -> 1392 | I10: =ROUND(G10-H10,2) -> 16008 | J10: =ROUND(I10*'Premissas'!$B$8+B10*(1-'Premissas'!$B$7)*'Premissas'!$B$9*'Premissas'!$B$6,2) -> 2136.79 | K10: =ROUND(I10-J10,2) -> 13871.21 | L10: =IF(A10>'Premissas'!$B$20,INDEX($K$5:$K$28,MAX(1,A10-'Premissas'!$B$20)),0) -> 9247.47 | M10: =ROUND(I10*'Premissas'!$B$10,2) -> 2401.2 | N10: =ROUND(I10*'Premissas'!$B$11,2) -> 480.24 | O10: =ROUND(B10*'Premissas'!$B$12*'Premissas'!$B$6,2) -> 6000 | P10: =ROUND(B10*'Premissas'!$B$13*'Premissas'!$B$6,2) -> 600 | Q10: =ROUND(D10*'Premissas'!$B$15,2) -> 0 | R10: =ROUND(Q10*'Premissas'!$B$19+Q9*(1-'Premissas'!$B$19),2) -> 15000 | S10: =ROUND(E10*'Premissas'!$B$17,2) -> 0 | T10: =ROUND(Q10*'Premissas'!$B$10,2) -> 0 | U10: =ROUND(R10*'Premissas'!$B$18,2) -> 750 | V10: =IF(A10<=12,'Premissas'!$B$24,'Premissas'!$B$25) -> 37000 | W10: =ROUND(G10+Q10,2) -> 17400 | X10: =ROUND(I10+Q10,2) -> 16008 | Y10: =ROUND(L10+R10,2) -> 24247.47 | Z10: =ROUND(SUM(M10:P10)+SUM(S10:V10),2) -> 47231.44 | AA10: =ROUND(Y10-Z10,2) -> -22983.97 | AB10: =ROUND(AB9+AA10,2) -> -316760.04 | AC10: =ROUND(X10-J10-SUM(M10:P10)-S10-T10-ROUND(Q10*'Premissas'!$B$18,2)-V10,2) -> -32610.23 | AD10: =ROUND(SUM($K$5:K10)-SUM($L$5:L10)+SUM($Q$5:Q10)-SUM($R$5:R10),2) -> 13871.21 | AE10: =MAX(0,AB10)*'Premissas'!$B$28 -> 0 | AF10: =IF(AB10>=0,A10,999) -> 999 | AG10: =IF(AE10>=Resumo!$E$5,A10,999) -> 999 | AH10: =AB10+Capital!$A$5 -> -216760.04 | AI10: =AB10+Capital!$A$6 -> -166760.04 | AJ10: =AB10+Capital!$A$7 -> -116760.04
A11: 7 | B11: 180 | C11: =ROUNDUP(B11/'Premissas'!$B$14,0) -> 9000 | D11: 0 | E11: =D11*'Premissas'!$B$16 -> 0 | F11: =ROUND(B11*'Premissas'!$B$5,2) -> 5220 | G11: =ROUND(F11*'Premissas'!$B$6,2) -> 26100 | H11: =ROUND(G11*'Premissas'!$B$7,2) -> 2088 | I11: =ROUND(G11-H11,2) -> 24012 | J11: =ROUND(I11*'Premissas'!$B$8+B11*(1-'Premissas'!$B$7)*'Premissas'!$B$9*'Premissas'!$B$6,2) -> 3205.19 | K11: =ROUND(I11-J11,2) -> 20806.81 | L11: =IF(A11>'Premissas'!$B$20,INDEX($K$5:$K$28,MAX(1,A11-'Premissas'!$B$20)),0) -> 13871.21 | M11: =ROUND(I11*'Premissas'!$B$10,2) -> 3601.8 | N11: =ROUND(I11*'Premissas'!$B$11,2) -> 720.36 | O11: =ROUND(B11*'Premissas'!$B$12*'Premissas'!$B$6,2) -> 9000 | P11: =ROUND(B11*'Premissas'!$B$13*'Premissas'!$B$6,2) -> 900 | Q11: =ROUND(D11*'Premissas'!$B$15,2) -> 0 | R11: =ROUND(Q11*'Premissas'!$B$19+Q10*(1-'Premissas'!$B$19),2) -> 0 | S11: =ROUND(E11*'Premissas'!$B$17,2) -> 0 | T11: =ROUND(Q11*'Premissas'!$B$10,2) -> 0 | U11: =ROUND(R11*'Premissas'!$B$18,2) -> 0 | V11: =IF(A11<=12,'Premissas'!$B$24,'Premissas'!$B$25) -> 37000 | W11: =ROUND(G11+Q11,2) -> 26100 | X11: =ROUND(I11+Q11,2) -> 24012 | Y11: =ROUND(L11+R11,2) -> 13871.21 | Z11: =ROUND(SUM(M11:P11)+SUM(S11:V11),2) -> 51222.16 | AA11: =ROUND(Y11-Z11,2) -> -37350.95 | AB11: =ROUND(AB10+AA11,2) -> -354110.99 | AC11: =ROUND(X11-J11-SUM(M11:P11)-S11-T11-ROUND(Q11*'Premissas'!$B$18,2)-V11,2) -> -30415.35 | AD11: =ROUND(SUM($K$5:K11)-SUM($L$5:L11)+SUM($Q$5:Q11)-SUM($R$5:R11),2) -> 20806.81 | AE11: =MAX(0,AB11)*'Premissas'!$B$28 -> 0 | AF11: =IF(AB11>=0,A11,999) -> 999 | AG11: =IF(AE11>=Resumo!$E$5,A11,999) -> 999 | AH11: =AB11+Capital!$A$5 -> -254110.99 | AI11: =AB11+Capital!$A$6 -> -204110.99 | AJ11: =AB11+Capital!$A$7 -> -154110.99
A12: 8 | B12: 250 | C12: =ROUNDUP(B12/'Premissas'!$B$14,0) -> 12500 | D12: 0 | E12: =D12*'Premissas'!$B$16 -> 0 | F12: =ROUND(B12*'Premissas'!$B$5,2) -> 7250 | G12: =ROUND(F12*'Premissas'!$B$6,2) -> 36250 | H12: =ROUND(G12*'Premissas'!$B$7,2) -> 2900 | I12: =ROUND(G12-H12,2) -> 33350 | J12: =ROUND(I12*'Premissas'!$B$8+B12*(1-'Premissas'!$B$7)*'Premissas'!$B$9*'Premissas'!$B$6,2) -> 4451.65 | K12: =ROUND(I12-J12,2) -> 28898.35 | L12: =IF(A12>'Premissas'!$B$20,INDEX($K$5:$K$28,MAX(1,A12-'Premissas'!$B$20)),0) -> 20806.81 | M12: =ROUND(I12*'Premissas'!$B$10,2) -> 5002.5 | N12: =ROUND(I12*'Premissas'!$B$11,2) -> 1000.5 | O12: =ROUND(B12*'Premissas'!$B$12*'Premissas'!$B$6,2) -> 12500 | P12: =ROUND(B12*'Premissas'!$B$13*'Premissas'!$B$6,2) -> 1250 | Q12: =ROUND(D12*'Premissas'!$B$15,2) -> 0 | R12: =ROUND(Q12*'Premissas'!$B$19+Q11*(1-'Premissas'!$B$19),2) -> 0 | S12: =ROUND(E12*'Premissas'!$B$17,2) -> 0 | T12: =ROUND(Q12*'Premissas'!$B$10,2) -> 0 | U12: =ROUND(R12*'Premissas'!$B$18,2) -> 0 | V12: =IF(A12<=12,'Premissas'!$B$24,'Premissas'!$B$25) -> 37000 | W12: =ROUND(G12+Q12,2) -> 36250 | X12: =ROUND(I12+Q12,2) -> 33350 | Y12: =ROUND(L12+R12,2) -> 20806.81 | Z12: =ROUND(SUM(M12:P12)+SUM(S12:V12),2) -> 56753 | AA12: =ROUND(Y12-Z12,2) -> -35946.19 | AB12: =ROUND(AB11+AA12,2) -> -390057.18 | AC12: =ROUND(X12-J12-SUM(M12:P12)-S12-T12-ROUND(Q12*'Premissas'!$B$18,2)-V12,2) -> -27854.65 | AD12: =ROUND(SUM($K$5:K12)-SUM($L$5:L12)+SUM($Q$5:Q12)-SUM($R$5:R12),2) -> 28898.35 | AE12: =MAX(0,AB12)*'Premissas'!$B$28 -> 0 | AF12: =IF(AB12>=0,A12,999) -> 999 | AG12: =IF(AE12>=Resumo!$E$5,A12,999) -> 999 | AH12: =AB12+Capital!$A$5 -> -290057.18 | AI12: =AB12+Capital!$A$6 -> -240057.18 | AJ12: =AB12+Capital!$A$7 -> -190057.18
A13: 9 | B13: 300 | C13: =ROUNDUP(B13/'Premissas'!$B$14,0) -> 15000 | D13: 1 | E13: =D13*'Premissas'!$B$16 -> 80 | F13: =ROUND(B13*'Premissas'!$B$5,2) -> 8700 | G13: =ROUND(F13*'Premissas'!$B$6,2) -> 43500 | H13: =ROUND(G13*'Premissas'!$B$7,2) -> 3480 | I13: =ROUND(G13-H13,2) -> 40020 | J13: =ROUND(I13*'Premissas'!$B$8+B13*(1-'Premissas'!$B$7)*'Premissas'!$B$9*'Premissas'!$B$6,2) -> 5341.98 | K13: =ROUND(I13-J13,2) -> 34678.02 | L13: =IF(A13>'Premissas'!$B$20,INDEX($K$5:$K$28,MAX(1,A13-'Premissas'!$B$20)),0) -> 28898.35 | M13: =ROUND(I13*'Premissas'!$B$10,2) -> 6003 | N13: =ROUND(I13*'Premissas'!$B$11,2) -> 1200.6 | O13: =ROUND(B13*'Premissas'!$B$12*'Premissas'!$B$6,2) -> 15000 | P13: =ROUND(B13*'Premissas'!$B$13*'Premissas'!$B$6,2) -> 1500 | Q13: =ROUND(D13*'Premissas'!$B$15,2) -> 30000 | R13: =ROUND(Q13*'Premissas'!$B$19+Q12*(1-'Premissas'!$B$19),2) -> 15000 | S13: =ROUND(E13*'Premissas'!$B$17,2) -> 14400 | T13: =ROUND(Q13*'Premissas'!$B$10,2) -> 4500 | U13: =ROUND(R13*'Premissas'!$B$18,2) -> 750 | V13: =IF(A13<=12,'Premissas'!$B$24,'Premissas'!$B$25) -> 37000 | W13: =ROUND(G13+Q13,2) -> 73500 | X13: =ROUND(I13+Q13,2) -> 70020 | Y13: =ROUND(L13+R13,2) -> 43898.35 | Z13: =ROUND(SUM(M13:P13)+SUM(S13:V13),2) -> 80353.6 | AA13: =ROUND(Y13-Z13,2) -> -36455.25 | AB13: =ROUND(AB12+AA13,2) -> -426512.43 | AC13: =ROUND(X13-J13-SUM(M13:P13)-S13-T13-ROUND(Q13*'Premissas'!$B$18,2)-V13,2) -> -16425.58 | AD13: =ROUND(SUM($K$5:K13)-SUM($L$5:L13)+SUM($Q$5:Q13)-SUM($R$5:R13),2) -> 49678.02 | AE13: =MAX(0,AB13)*'Premissas'!$B$28 -> 0 | AF13: =IF(AB13>=0,A13,999) -> 999 | AG13: =IF(AE13>=Resumo!$E$5,A13,999) -> 999 | AH13: =AB13+Capital!$A$5 -> -326512.43 | AI13: =AB13+Capital!$A$6 -> -276512.43 | AJ13: =AB13+Capital!$A$7 -> -226512.43
A14: 10 | B14: 350 | C14: =ROUNDUP(B14/'Premissas'!$B$14,0) -> 17500 | D14: 0 | E14: =D14*'Premissas'!$B$16 -> 0 | F14: =ROUND(B14*'Premissas'!$B$5,2) -> 10150 | G14: =ROUND(F14*'Premissas'!$B$6,2) -> 50750 | H14: =ROUND(G14*'Premissas'!$B$7,2) -> 4060 | I14: =ROUND(G14-H14,2) -> 46690 | J14: =ROUND(I14*'Premissas'!$B$8+B14*(1-'Premissas'!$B$7)*'Premissas'!$B$9*'Premissas'!$B$6,2) -> 6232.31 | K14: =ROUND(I14-J14,2) -> 40457.69 | L14: =IF(A14>'Premissas'!$B$20,INDEX($K$5:$K$28,MAX(1,A14-'Premissas'!$B$20)),0) -> 34678.02 | M14: =ROUND(I14*'Premissas'!$B$10,2) -> 7003.5 | N14: =ROUND(I14*'Premissas'!$B$11,2) -> 1400.7 | O14: =ROUND(B14*'Premissas'!$B$12*'Premissas'!$B$6,2) -> 17500 | P14: =ROUND(B14*'Premissas'!$B$13*'Premissas'!$B$6,2) -> 1750 | Q14: =ROUND(D14*'Premissas'!$B$15,2) -> 0 | R14: =ROUND(Q14*'Premissas'!$B$19+Q13*(1-'Premissas'!$B$19),2) -> 15000 | S14: =ROUND(E14*'Premissas'!$B$17,2) -> 0 | T14: =ROUND(Q14*'Premissas'!$B$10,2) -> 0 | U14: =ROUND(R14*'Premissas'!$B$18,2) -> 750 | V14: =IF(A14<=12,'Premissas'!$B$24,'Premissas'!$B$25) -> 37000 | W14: =ROUND(G14+Q14,2) -> 50750 | X14: =ROUND(I14+Q14,2) -> 46690 | Y14: =ROUND(L14+R14,2) -> 49678.02 | Z14: =ROUND(SUM(M14:P14)+SUM(S14:V14),2) -> 65404.2 | AA14: =ROUND(Y14-Z14,2) -> -15726.18 | AB14: =ROUND(AB13+AA14,2) -> -442238.61 | AC14: =ROUND(X14-J14-SUM(M14:P14)-S14-T14-ROUND(Q14*'Premissas'!$B$18,2)-V14,2) -> -24196.51 | AD14: =ROUND(SUM($K$5:K14)-SUM($L$5:L14)+SUM($Q$5:Q14)-SUM($R$5:R14),2) -> 40457.69 | AE14: =MAX(0,AB14)*'Premissas'!$B$28 -> 0 | AF14: =IF(AB14>=0,A14,999) -> 999 | AG14: =IF(AE14>=Resumo!$E$5,A14,999) -> 999 | AH14: =AB14+Capital!$A$5 -> -342238.61 | AI14: =AB14+Capital!$A$6 -> -292238.61 | AJ14: =AB14+Capital!$A$7 -> -242238.61
A15: 11 | B15: 400 | C15: =ROUNDUP(B15/'Premissas'!$B$14,0) -> 20000 | D15: 0 | E15: =D15*'Premissas'!$B$16 -> 0 | F15: =ROUND(B15*'Premissas'!$B$5,2) -> 11600 | G15: =ROUND(F15*'Premissas'!$B$6,2) -> 58000 | H15: =ROUND(G15*'Premissas'!$B$7,2) -> 4640 | I15: =ROUND(G15-H15,2) -> 53360 | J15: =ROUND(I15*'Premissas'!$B$8+B15*(1-'Premissas'!$B$7)*'Premissas'!$B$9*'Premissas'!$B$6,2) -> 7122.64 | K15: =ROUND(I15-J15,2) -> 46237.36 | L15: =IF(A15>'Premissas'!$B$20,INDEX($K$5:$K$28,MAX(1,A15-'Premissas'!$B$20)),0) -> 40457.69 | M15: =ROUND(I15*'Premissas'!$B$10,2) -> 8004 | N15: =ROUND(I15*'Premissas'!$B$11,2) -> 1600.8 | O15: =ROUND(B15*'Premissas'!$B$12*'Premissas'!$B$6,2) -> 20000 | P15: =ROUND(B15*'Premissas'!$B$13*'Premissas'!$B$6,2) -> 2000 | Q15: =ROUND(D15*'Premissas'!$B$15,2) -> 0 | R15: =ROUND(Q15*'Premissas'!$B$19+Q14*(1-'Premissas'!$B$19),2) -> 0 | S15: =ROUND(E15*'Premissas'!$B$17,2) -> 0 | T15: =ROUND(Q15*'Premissas'!$B$10,2) -> 0 | U15: =ROUND(R15*'Premissas'!$B$18,2) -> 0 | V15: =IF(A15<=12,'Premissas'!$B$24,'Premissas'!$B$25) -> 37000 | W15: =ROUND(G15+Q15,2) -> 58000 | X15: =ROUND(I15+Q15,2) -> 53360 | Y15: =ROUND(L15+R15,2) -> 40457.69 | Z15: =ROUND(SUM(M15:P15)+SUM(S15:V15),2) -> 68604.8 | AA15: =ROUND(Y15-Z15,2) -> -28147.11 | AB15: =ROUND(AB14+AA15,2) -> -470385.72 | AC15: =ROUND(X15-J15-SUM(M15:P15)-S15-T15-ROUND(Q15*'Premissas'!$B$18,2)-V15,2) -> -22367.44 | AD15: =ROUND(SUM($K$5:K15)-SUM($L$5:L15)+SUM($Q$5:Q15)-SUM($R$5:R15),2) -> 46237.36 | AE15: =MAX(0,AB15)*'Premissas'!$B$28 -> 0 | AF15: =IF(AB15>=0,A15,999) -> 999 | AG15: =IF(AE15>=Resumo!$E$5,A15,999) -> 999 | AH15: =AB15+Capital!$A$5 -> -370385.72 | AI15: =AB15+Capital!$A$6 -> -320385.72 | AJ15: =AB15+Capital!$A$7 -> -270385.72
A16: 12 | B16: 450 | C16: =ROUNDUP(B16/'Premissas'!$B$14,0) -> 22500 | D16: 0 | E16: =D16*'Premissas'!$B$16 -> 0 | F16: =ROUND(B16*'Premissas'!$B$5,2) -> 13050 | G16: =ROUND(F16*'Premissas'!$B$6,2) -> 65250 | H16: =ROUND(G16*'Premissas'!$B$7,2) -> 5220 | I16: =ROUND(G16-H16,2) -> 60030 | J16: =ROUND(I16*'Premissas'!$B$8+B16*(1-'Premissas'!$B$7)*'Premissas'!$B$9*'Premissas'!$B$6,2) -> 8012.97 | K16: =ROUND(I16-J16,2) -> 52017.03 | L16: =IF(A16>'Premissas'!$B$20,INDEX($K$5:$K$28,MAX(1,A16-'Premissas'!$B$20)),0) -> 46237.36 | M16: =ROUND(I16*'Premissas'!$B$10,2) -> 9004.5 | N16: =ROUND(I16*'Premissas'!$B$11,2) -> 1800.9 | O16: =ROUND(B16*'Premissas'!$B$12*'Premissas'!$B$6,2) -> 22500 | P16: =ROUND(B16*'Premissas'!$B$13*'Premissas'!$B$6,2) -> 2250 | Q16: =ROUND(D16*'Premissas'!$B$15,2) -> 0 | R16: =ROUND(Q16*'Premissas'!$B$19+Q15*(1-'Premissas'!$B$19),2) -> 0 | S16: =ROUND(E16*'Premissas'!$B$17,2) -> 0 | T16: =ROUND(Q16*'Premissas'!$B$10,2) -> 0 | U16: =ROUND(R16*'Premissas'!$B$18,2) -> 0 | V16: =IF(A16<=12,'Premissas'!$B$24,'Premissas'!$B$25) -> 37000 | W16: =ROUND(G16+Q16,2) -> 65250 | X16: =ROUND(I16+Q16,2) -> 60030 | Y16: =ROUND(L16+R16,2) -> 46237.36 | Z16: =ROUND(SUM(M16:P16)+SUM(S16:V16),2) -> 72555.4 | AA16: =ROUND(Y16-Z16,2) -> -26318.04 | AB16: =ROUND(AB15+AA16,2) -> -496703.76 | AC16: =ROUND(X16-J16-SUM(M16:P16)-S16-T16-ROUND(Q16*'Premissas'!$B$18,2)-V16,2) -> -20538.37 | AD16: =ROUND(SUM($K$5:K16)-SUM($L$5:L16)+SUM($Q$5:Q16)-SUM($R$5:R16),2) -> 52017.03 | AE16: =MAX(0,AB16)*'Premissas'!$B$28 -> 0 | AF16: =IF(AB16>=0,A16,999) -> 999 | AG16: =IF(AE16>=Resumo!$E$5,A16,999) -> 999 | AH16: =AB16+Capital!$A$5 -> -396703.76 | AI16: =AB16+Capital!$A$6 -> -346703.76 | AJ16: =AB16+Capital!$A$7 -> -296703.76
A17: 13 | B17: 500 | C17: =ROUNDUP(B17/'Premissas'!$B$14,0) -> 25000 | D17: 1 | E17: =D17*'Premissas'!$B$16 -> 80 | F17: =ROUND(B17*'Premissas'!$B$5,2) -> 14500 | G17: =ROUND(F17*'Premissas'!$B$6,2) -> 72500 | H17: =ROUND(G17*'Premissas'!$B$7,2) -> 5800 | I17: =ROUND(G17-H17,2) -> 66700 | J17: =ROUND(I17*'Premissas'!$B$8+B17*(1-'Premissas'!$B$7)*'Premissas'!$B$9*'Premissas'!$B$6,2) -> 8903.3 | K17: =ROUND(I17-J17,2) -> 57796.7 | L17: =IF(A17>'Premissas'!$B$20,INDEX($K$5:$K$28,MAX(1,A17-'Premissas'!$B$20)),0) -> 52017.03 | M17: =ROUND(I17*'Premissas'!$B$10,2) -> 10005 | N17: =ROUND(I17*'Premissas'!$B$11,2) -> 2001 | O17: =ROUND(B17*'Premissas'!$B$12*'Premissas'!$B$6,2) -> 25000 | P17: =ROUND(B17*'Premissas'!$B$13*'Premissas'!$B$6,2) -> 2500 | Q17: =ROUND(D17*'Premissas'!$B$15,2) -> 30000 | R17: =ROUND(Q17*'Premissas'!$B$19+Q16*(1-'Premissas'!$B$19),2) -> 15000 | S17: =ROUND(E17*'Premissas'!$B$17,2) -> 14400 | T17: =ROUND(Q17*'Premissas'!$B$10,2) -> 4500 | U17: =ROUND(R17*'Premissas'!$B$18,2) -> 750 | V17: =IF(A17<=12,'Premissas'!$B$24,'Premissas'!$B$25) -> 42000 | W17: =ROUND(G17+Q17,2) -> 102500 | X17: =ROUND(I17+Q17,2) -> 96700 | Y17: =ROUND(L17+R17,2) -> 67017.03 | Z17: =ROUND(SUM(M17:P17)+SUM(S17:V17),2) -> 101156 | AA17: =ROUND(Y17-Z17,2) -> -34138.97 | AB17: =ROUND(AB16+AA17,2) -> -530842.73 | AC17: =ROUND(X17-J17-SUM(M17:P17)-S17-T17-ROUND(Q17*'Premissas'!$B$18,2)-V17,2) -> -14109.3 | AD17: =ROUND(SUM($K$5:K17)-SUM($L$5:L17)+SUM($Q$5:Q17)-SUM($R$5:R17),2) -> 72796.7 | AE17: =MAX(0,AB17)*'Premissas'!$B$28 -> 0 | AF17: =IF(AB17>=0,A17,999) -> 999 | AG17: =IF(AE17>=Resumo!$E$5,A17,999) -> 999 | AH17: =AB17+Capital!$A$5 -> -430842.73 | AI17: =AB17+Capital!$A$6 -> -380842.73 | AJ17: =AB17+Capital!$A$7 -> -330842.73
... A28: 24 | B28: 750 | C28: =ROUNDUP(B28/'Premissas'!$B$14,0) -> 37500 | D28: 0 | E28: =D28*'Premissas'!$B$16 -> 0 | F28: =ROUND(B28*'Premissas'!$B$5,2) -> 21750 | G28: =ROUND(F28*'Premissas'!$B$6,2) -> 108750 | H28: =ROUND(G28*'Premissas'!$B$7,2) -> 8700 | I28: =ROUND(G28-H28,2) -> 100050 | J28: =ROUND(I28*'Premissas'!$B$8+B28*(1-'Premissas'!$B$7)*'Premissas'!$B$9*'Premissas'!$B$6,2) -> 13354.95 | K28: =ROUND(I28-J28,2) -> 86695.05 | L28: =IF(A28>'Premissas'!$B$20,INDEX($K$5:$K$28,MAX(1,A28-'Premissas'!$B$20)),0) -> 80915.38 | M28: =ROUND(I28*'Premissas'!$B$10,2) -> 15007.5 | N28: =ROUND(I28*'Premissas'!$B$11,2) -> 3001.5 | O28: =ROUND(B28*'Premissas'!$B$12*'Premissas'!$B$6,2) -> 37500 | P28: =ROUND(B28*'Premissas'!$B$13*'Premissas'!$B$6,2) -> 3750 | Q28: =ROUND(D28*'Premissas'!$B$15,2) -> 0 | R28: =ROUND(Q28*'Premissas'!$B$19+Q27*(1-'Premissas'!$B$19),2) -> 0 | S28: =ROUND(E28*'Premissas'!$B$17,2) -> 0 | T28: =ROUND(Q28*'Premissas'!$B$10,2) -> 0 | U28: =ROUND(R28*'Premissas'!$B$18,2) -> 0 | V28: =IF(A28<=12,'Premissas'!$B$24,'Premissas'!$B$25) -> 42000 | W28: =ROUND(G28+Q28,2) -> 108750 | X28: =ROUND(I28+Q28,2) -> 100050 | Y28: =ROUND(L28+R28,2) -> 80915.38 | Z28: =ROUND(SUM(M28:P28)+SUM(S28:V28),2) -> 101259 | AA28: =ROUND(Y28-Z28,2) -> -20343.62 | AB28: =ROUND(AB27+AA28,2) -> -737708.49 | AC28: =ROUND(X28-J28-SUM(M28:P28)-S28-T28-ROUND(Q28*'Premissas'!$B$18,2)-V28,2) -> -14563.95 | AD28: =ROUND(SUM($K$5:K28)-SUM($L$5:L28)+SUM($Q$5:Q28)-SUM($R$5:R28),2) -> 86695.05 | AE28: =MAX(0,AB28)*'Premissas'!$B$28 -> 0 | AF28: =IF(AB28>=0,A28,999) -> 999 | AG28: =IF(AE28>=Resumo!$E$5,A28,999) -> 999 | AH28: =AB28+Capital!$A$5 -> -637708.49 | AI28: =AB28+Capital!$A$6 -> -587708.49 | AJ28: =AB28+Capital!$A$7 -> -537708.49

Sheet Base
A1: Base | fluxo mensal em BRL, salvo indicação
A2: Agenda editável em azul. Cenário hipotético; não previsão. | M0 separado: -R$100 mil nas premissas. Acumulado exclui aportes/distribuição.
A4: Mês | B4: Pedidos aprovados | C4: Visitas qualificadas | D4: Mapas faturados | E4: Horas diretas TI | F4: Loja bruta USD | G4: Loja bruta BRL | H4: Estornos BRL | I4: Loja após estornos BRL | J4: Taxa plataforma BRL | K4: Liquidação gerada BRL | L4: Loja recebida BRL | M4: Tributos loja BRL | N4: Reserva meios/FX BRL | O4: Aquisição / mídia BRL | P4: Suporte loja BRL | Q4: Fatura TI BRL | R4: Recebimentos TI BRL | S4: Entrega TI BRL | T4: Tributos TI BRL | U4: Comercial TI caixa BRL | V4: Fixo BRL | W4: Vendas brutas BRL | X4: Receita após estornos BRL | Y4: Recebimentos BRL | Z4: Saídas caixa BRL | AA4: Fluxo líquido BRL | AB4: Acumulado sem aporte BRL | AC4: Resultado competência BRL | AD4: A receber BRL | AE4: 50% excedente positivo BRL | AF4: Mês elegível payback projeto | AG4: Mês elegível Dani hipotético | AH4: Saldo com 100k | AI4: Saldo com 150k | AJ4: Saldo com 200k
A5: 1 | B5: 0 | C5: =ROUNDUP(B5/'Premissas'!$B$14,0) -> 0 | D5: 0 | E5: =D5*'Premissas'!$B$16 -> 0 | F5: =ROUND(B5*'Premissas'!$B$5,2) -> 0 | G5: =ROUND(F5*'Premissas'!$B$6,2) -> 0 | H5: =ROUND(G5*'Premissas'!$B$7,2) -> 0 | I5: =ROUND(G5-H5,2) -> 0 | J5: =ROUND(I5*'Premissas'!$B$8+B5*(1-'Premissas'!$B$7)*'Premissas'!$B$9*'Premissas'!$B$6,2) -> 0 | K5: =ROUND(I5-J5,2) -> 0 | L5: =IF(A5>'Premissas'!$B$20,INDEX($K$5:$K$28,MAX(1,A5-'Premissas'!$B$20)),0) -> 0 | M5: =ROUND(I5*'Premissas'!$B$10,2) -> 0 | N5: =ROUND(I5*'Premissas'!$B$11,2) -> 0 | O5: =ROUND(B5*'Premissas'!$B$12*'Premissas'!$B$6,2) -> 0 | P5: =ROUND(B5*'Premissas'!$B$13*'Premissas'!$B$6,2) -> 0 | Q5: =ROUND(D5*'Premissas'!$B$15,2) -> 0 | R5: =ROUND(Q5*'Premissas'!$B$19+0*(1-'Premissas'!$B$19),2) -> 0 | S5: =ROUND(E5*'Premissas'!$B$17,2) -> 0 | T5: =ROUND(Q5*'Premissas'!$B$10,2) -> 0 | U5: =ROUND(R5*'Premissas'!$B$18,2) -> 0 | V5: =IF(A5<=12,'Premissas'!$B$24,'Premissas'!$B$25) -> 37000 | W5: =ROUND(G5+Q5,2) -> 0 | X5: =ROUND(I5+Q5,2) -> 0 | Y5: =ROUND(L5+R5,2) -> 0 | Z5: =ROUND(SUM(M5:P5)+SUM(S5:V5),2) -> 37000 | AA5: =ROUND(Y5-Z5,2) -> -37000 | AB5: =ROUND(-'Premissas'!$B$23+AA5,2) -> -137000 | AC5: =ROUND(X5-J5-SUM(M5:P5)-S5-T5-ROUND(Q5*'Premissas'!$B$18,2)-V5,2) -> -37000 | AD5: =ROUND(SUM($K$5:K5)-SUM($L$5:L5)+SUM($Q$5:Q5)-SUM($R$5:R5),2) -> 0 | AE5: =MAX(0,AB5)*'Premissas'!$B$28 -> 0 | AF5: =IF(AB5>=0,A5,999) -> 999 | AG5: =IF(AE5>=Resumo!$E$6,A5,999) -> 999 | AH5: =AB5+Capital!$A$5 -> -37000 | AI5: =AB5+Capital!$A$6 -> 13000 | AJ5: =AB5+Capital!$A$7 -> 63000
A6: 2 | B6: 0 | C6: =ROUNDUP(B6/'Premissas'!$B$14,0) -> 0 | D6: 0 | E6: =D6*'Premissas'!$B$16 -> 0 | F6: =ROUND(B6*'Premissas'!$B$5,2) -> 0 | G6: =ROUND(F6*'Premissas'!$B$6,2) -> 0 | H6: =ROUND(G6*'Premissas'!$B$7,2) -> 0 | I6: =ROUND(G6-H6,2) -> 0 | J6: =ROUND(I6*'Premissas'!$B$8+B6*(1-'Premissas'!$B$7)*'Premissas'!$B$9*'Premissas'!$B$6,2) -> 0 | K6: =ROUND(I6-J6,2) -> 0 | L6: =IF(A6>'Premissas'!$B$20,INDEX($K$5:$K$28,MAX(1,A6-'Premissas'!$B$20)),0) -> 0 | M6: =ROUND(I6*'Premissas'!$B$10,2) -> 0 | N6: =ROUND(I6*'Premissas'!$B$11,2) -> 0 | O6: =ROUND(B6*'Premissas'!$B$12*'Premissas'!$B$6,2) -> 0 | P6: =ROUND(B6*'Premissas'!$B$13*'Premissas'!$B$6,2) -> 0 | Q6: =ROUND(D6*'Premissas'!$B$15,2) -> 0 | R6: =ROUND(Q6*'Premissas'!$B$19+Q5*(1-'Premissas'!$B$19),2) -> 0 | S6: =ROUND(E6*'Premissas'!$B$17,2) -> 0 | T6: =ROUND(Q6*'Premissas'!$B$10,2) -> 0 | U6: =ROUND(R6*'Premissas'!$B$18,2) -> 0 | V6: =IF(A6<=12,'Premissas'!$B$24,'Premissas'!$B$25) -> 37000 | W6: =ROUND(G6+Q6,2) -> 0 | X6: =ROUND(I6+Q6,2) -> 0 | Y6: =ROUND(L6+R6,2) -> 0 | Z6: =ROUND(SUM(M6:P6)+SUM(S6:V6),2) -> 37000 | AA6: =ROUND(Y6-Z6,2) -> -37000 | AB6: =ROUND(AB5+AA6,2) -> -174000 | AC6: =ROUND(X6-J6-SUM(M6:P6)-S6-T6-ROUND(Q6*'Premissas'!$B$18,2)-V6,2) -> -37000 | AD6: =ROUND(SUM($K$5:K6)-SUM($L$5:L6)+SUM($Q$5:Q6)-SUM($R$5:R6),2) -> 0 | AE6: =MAX(0,AB6)*'Premissas'!$B$28 -> 0 | AF6: =IF(AB6>=0,A6,999) -> 999 | AG6: =IF(AE6>=Resumo!$E$6,A6,999) -> 999 | AH6: =AB6+Capital!$A$5 -> -74000 | AI6: =AB6+Capital!$A$6 -> -24000 | AJ6: =AB6+Capital!$A$7 -> 26000
A7: 3 | B7: 50 | C7: =ROUNDUP(B7/'Premissas'!$B$14,0) -> 2500 | D7: 1 | E7: =D7*'Premissas'!$B$16 -> 80 | F7: =ROUND(B7*'Premissas'!$B$5,2) -> 1450 | G7: =ROUND(F7*'Premissas'!$B$6,2) -> 7250 | H7: =ROUND(G7*'Premissas'!$B$7,2) -> 580 | I7: =ROUND(G7-H7,2) -> 6670 | J7: =ROUND(I7*'Premissas'!$B$8+B7*(1-'Premissas'!$B$7)*'Premissas'!$B$9*'Premissas'!$B$6,2) -> 890.33 | K7: =ROUND(I7-J7,2) -> 5779.67 | L7: =IF(A7>'Premissas'!$B$20,INDEX($K$5:$K$28,MAX(1,A7-'Premissas'!$B$20)),0) -> 0 | M7: =ROUND(I7*'Premissas'!$B$10,2) -> 1000.5 | N7: =ROUND(I7*'Premissas'!$B$11,2) -> 200.1 | O7: =ROUND(B7*'Premissas'!$B$12*'Premissas'!$B$6,2) -> 2500 | P7: =ROUND(B7*'Premissas'!$B$13*'Premissas'!$B$6,2) -> 250 | Q7: =ROUND(D7*'Premissas'!$B$15,2) -> 30000 | R7: =ROUND(Q7*'Premissas'!$B$19+Q6*(1-'Premissas'!$B$19),2) -> 15000 | S7: =ROUND(E7*'Premissas'!$B$17,2) -> 14400 | T7: =ROUND(Q7*'Premissas'!$B$10,2) -> 4500 | U7: =ROUND(R7*'Premissas'!$B$18,2) -> 750 | V7: =IF(A7<=12,'Premissas'!$B$24,'Premissas'!$B$25) -> 37000 | W7: =ROUND(G7+Q7,2) -> 37250 | X7: =ROUND(I7+Q7,2) -> 36670 | Y7: =ROUND(L7+R7,2) -> 15000 | Z7: =ROUND(SUM(M7:P7)+SUM(S7:V7),2) -> 60600.6 | AA7: =ROUND(Y7-Z7,2) -> -45600.6 | AB7: =ROUND(AB6+AA7,2) -> -219600.6 | AC7: =ROUND(X7-J7-SUM(M7:P7)-S7-T7-ROUND(Q7*'Premissas'!$B$18,2)-V7,2) -> -25570.93 | AD7: =ROUND(SUM($K$5:K7)-SUM($L$5:L7)+SUM($Q$5:Q7)-SUM($R$5:R7),2) -> 20779.67 | AE7: =MAX(0,AB7)*'Premissas'!$B$28 -> 0 | AF7: =IF(AB7>=0,A7,999) -> 999 | AG7: =IF(AE7>=Resumo!$E$6,A7,999) -> 999 | AH7: =AB7+Capital!$A$5 -> -119600.6 | AI7: =AB7+Capital!$A$6 -> -69600.6 | AJ7: =AB7+Capital!$A$7 -> -19600.6
A8: 4 | B8: 150 | C8: =ROUNDUP(B8/'Premissas'!$B$14,0) -> 7500 | D8: 0 | E8: =D8*'Premissas'!$B$16 -> 0 | F8: =ROUND(B8*'Premissas'!$B$5,2) -> 4350 | G8: =ROUND(F8*'Premissas'!$B$6,2) -> 21750 | H8: =ROUND(G8*'Premissas'!$B$7,2) -> 1740 | I8: =ROUND(G8-H8,2) -> 20010 | J8: =ROUND(I8*'Premissas'!$B$8+B8*(1-'Premissas'!$B$7)*'Premissas'!$B$9*'Premissas'!$B$6,2) -> 2670.99 | K8: =ROUND(I8-J8,2) -> 17339.01 | L8: =IF(A8>'Premissas'!$B$20,INDEX($K$5:$K$28,MAX(1,A8-'Premissas'!$B$20)),0) -> 5779.67 | M8: =ROUND(I8*'Premissas'!$B$10,2) -> 3001.5 | N8: =ROUND(I8*'Premissas'!$B$11,2) -> 600.3 | O8: =ROUND(B8*'Premissas'!$B$12*'Premissas'!$B$6,2) -> 7500 | P8: =ROUND(B8*'Premissas'!$B$13*'Premissas'!$B$6,2) -> 750 | Q8: =ROUND(D8*'Premissas'!$B$15,2) -> 0 | R8: =ROUND(Q8*'Premissas'!$B$19+Q7*(1-'Premissas'!$B$19),2) -> 15000 | S8: =ROUND(E8*'Premissas'!$B$17,2) -> 0 | T8: =ROUND(Q8*'Premissas'!$B$10,2) -> 0 | U8: =ROUND(R8*'Premissas'!$B$18,2) -> 750 | V8: =IF(A8<=12,'Premissas'!$B$24,'Premissas'!$B$25) -> 37000 | W8: =ROUND(G8+Q8,2) -> 21750 | X8: =ROUND(I8+Q8,2) -> 20010 | Y8: =ROUND(L8+R8,2) -> 20779.67 | Z8: =ROUND(SUM(M8:P8)+SUM(S8:V8),2) -> 49601.8 | AA8: =ROUND(Y8-Z8,2) -> -28822.13 | AB8: =ROUND(AB7+AA8,2) -> -248422.73 | AC8: =ROUND(X8-J8-SUM(M8:P8)-S8-T8-ROUND(Q8*'Premissas'!$B$18,2)-V8,2) -> -31512.79 | AD8: =ROUND(SUM($K$5:K8)-SUM($L$5:L8)+SUM($Q$5:Q8)-SUM($R$5:R8),2) -> 17339.01 | AE8: =MAX(0,AB8)*'Premissas'!$B$28 -> 0 | AF8: =IF(AB8>=0,A8,999) -> 999 | AG8: =IF(AE8>=Resumo!$E$6,A8,999) -> 999 | AH8: =AB8+Capital!$A$5 -> -148422.73 | AI8: =AB8+Capital!$A$6 -> -98422.73 | AJ8: =AB8+Capital!$A$7 -> -48422.73
A9: 5 | B9: 300 | C9: =ROUNDUP(B9/'Premissas'!$B$14,0) -> 15000 | D9: 1 | E9: =D9*'Premissas'!$B$16 -> 80 | F9: =ROUND(B9*'Premissas'!$B$5,2) -> 8700 | G9: =ROUND(F9*'Premissas'!$B$6,2) -> 43500 | H9: =ROUND(G9*'Premissas'!$B$7,2) -> 3480 | I9: =ROUND(G9-H9,2) -> 40020 | J9: =ROUND(I9*'Premissas'!$B$8+B9*(1-'Premissas'!$B$7)*'Premissas'!$B$9*'Premissas'!$B$6,2) -> 5341.98 | K9: =ROUND(I9-J9,2) -> 34678.02 | L9: =IF(A9>'Premissas'!$B$20,INDEX($K$5:$K$28,MAX(1,A9-'Premissas'!$B$20)),0) -> 17339.01 | M9: =ROUND(I9*'Premissas'!$B$10,2) -> 6003 | N9: =ROUND(I9*'Premissas'!$B$11,2) -> 1200.6 | O9: =ROUND(B9*'Premissas'!$B$12*'Premissas'!$B$6,2) -> 15000 | P9: =ROUND(B9*'Premissas'!$B$13*'Premissas'!$B$6,2) -> 1500 | Q9: =ROUND(D9*'Premissas'!$B$15,2) -> 30000 | R9: =ROUND(Q9*'Premissas'!$B$19+Q8*(1-'Premissas'!$B$19),2) -> 15000 | S9: =ROUND(E9*'Premissas'!$B$17,2) -> 14400 | T9: =ROUND(Q9*'Premissas'!$B$10,2) -> 4500 | U9: =ROUND(R9*'Premissas'!$B$18,2) -> 750 | V9: =IF(A9<=12,'Premissas'!$B$24,'Premissas'!$B$25) -> 37000 | W9: =ROUND(G9+Q9,2) -> 73500 | X9: =ROUND(I9+Q9,2) -> 70020 | Y9: =ROUND(L9+R9,2) -> 32339.01 | Z9: =ROUND(SUM(M9:P9)+SUM(S9:V9),2) -> 80353.6 | AA9: =ROUND(Y9-Z9,2) -> -48014.59 | AB9: =ROUND(AB8+AA9,2) -> -296437.32 | AC9: =ROUND(X9-J9-SUM(M9:P9)-S9-T9-ROUND(Q9*'Premissas'!$B$18,2)-V9,2) -> -16425.58 | AD9: =ROUND(SUM($K$5:K9)-SUM($L$5:L9)+SUM($Q$5:Q9)-SUM($R$5:R9),2) -> 49678.02 | AE9: =MAX(0,AB9)*'Premissas'!$B$28 -> 0 | AF9: =IF(AB9>=0,A9,999) -> 999 | AG9: =IF(AE9>=Resumo!$E$6,A9,999) -> 999 | AH9: =AB9+Capital!$A$5 -> -196437.32 | AI9: =AB9+Capital!$A$6 -> -146437.32 | AJ9: =AB9+Capital!$A$7 -> -96437.32
A10: 6 | B10: 500 | C10: =ROUNDUP(B10/'Premissas'!$B$14,0) -> 25000 | D10: 0 | E10: =D10*'Premissas'!$B$16 -> 0 | F10: =ROUND(B10*'Premissas'!$B$5,2) -> 14500 | G10: =ROUND(F10*'Premissas'!$B$6,2) -> 72500 | H10: =ROUND(G10*'Premissas'!$B$7,2) -> 5800 | I10: =ROUND(G10-H10,2) -> 66700 | J10: =ROUND(I10*'Premissas'!$B$8+B10*(1-'Premissas'!$B$7)*'Premissas'!$B$9*'Premissas'!$B$6,2) -> 8903.3 | K10: =ROUND(I10-J10,2) -> 57796.7 | L10: =IF(A10>'Premissas'!$B$20,INDEX($K$5:$K$28,MAX(1,A10-'Premissas'!$B$20)),0) -> 34678.02 | M10: =ROUND(I10*'Premissas'!$B$10,2) -> 10005 | N10: =ROUND(I10*'Premissas'!$B$11,2) -> 2001 | O10: =ROUND(B10*'Premissas'!$B$12*'Premissas'!$B$6,2) -> 25000 | P10: =ROUND(B10*'Premissas'!$B$13*'Premissas'!$B$6,2) -> 2500 | Q10: =ROUND(D10*'Premissas'!$B$15,2) -> 0 | R10: =ROUND(Q10*'Premissas'!$B$19+Q9*(1-'Premissas'!$B$19),2) -> 15000 | S10: =ROUND(E10*'Premissas'!$B$17,2) -> 0 | T10: =ROUND(Q10*'Premissas'!$B$10,2) -> 0 | U10: =ROUND(R10*'Premissas'!$B$18,2) -> 750 | V10: =IF(A10<=12,'Premissas'!$B$24,'Premissas'!$B$25) -> 37000 | W10: =ROUND(G10+Q10,2) -> 72500 | X10: =ROUND(I10+Q10,2) -> 66700 | Y10: =ROUND(L10+R10,2) -> 49678.02 | Z10: =ROUND(SUM(M10:P10)+SUM(S10:V10),2) -> 77256 | AA10: =ROUND(Y10-Z10,2) -> -27577.98 | AB10: =ROUND(AB9+AA10,2) -> -324015.3 | AC10: =ROUND(X10-J10-SUM(M10:P10)-S10-T10-ROUND(Q10*'Premissas'!$B$18,2)-V10,2) -> -18709.3 | AD10: =ROUND(SUM($K$5:K10)-SUM($L$5:L10)+SUM($Q$5:Q10)-SUM($R$5:R10),2) -> 57796.7 | AE10: =MAX(0,AB10)*'Premissas'!$B$28 -> 0 | AF10: =IF(AB10>=0,A10,999) -> 999 | AG10: =IF(AE10>=Resumo!$E$6,A10,999) -> 999 | AH10: =AB10+Capital!$A$5 -> -224015.3 | AI10: =AB10+Capital!$A$6 -> -174015.3 | AJ10: =AB10+Capital!$A$7 -> -124015.3
A11: 7 | B11: 750 | C11: =ROUNDUP(B11/'Premissas'!$B$14,0) -> 37500 | D11: 1 | E11: =D11*'Premissas'!$B$16 -> 80 | F11: =ROUND(B11*'Premissas'!$B$5,2) -> 21750 | G11: =ROUND(F11*'Premissas'!$B$6,2) -> 108750 | H11: =ROUND(G11*'Premissas'!$B$7,2) -> 8700 | I11: =ROUND(G11-H11,2) -> 100050 | J11: =ROUND(I11*'Premissas'!$B$8+B11*(1-'Premissas'!$B$7)*'Premissas'!$B$9*'Premissas'!$B$6,2) -> 13354.95 | K11: =ROUND(I11-J11,2) -> 86695.05 | L11: =IF(A11>'Premissas'!$B$20,INDEX($K$5:$K$28,MAX(1,A11-'Premissas'!$B$20)),0) -> 57796.7 | M11: =ROUND(I11*'Premissas'!$B$10,2) -> 15007.5 | N11: =ROUND(I11*'Premissas'!$B$11,2) -> 3001.5 | O11: =ROUND(B11*'Premissas'!$B$12*'Premissas'!$B$6,2) -> 37500 | P11: =ROUND(B11*'Premissas'!$B$13*'Premissas'!$B$6,2) -> 3750 | Q11: =ROUND(D11*'Premissas'!$B$15,2) -> 30000 | R11: =ROUND(Q11*'Premissas'!$B$19+Q10*(1-'Premissas'!$B$19),2) -> 15000 | S11: =ROUND(E11*'Premissas'!$B$17,2) -> 14400 | T11: =ROUND(Q11*'Premissas'!$B$10,2) -> 4500 | U11: =ROUND(R11*'Premissas'!$B$18,2) -> 750 | V11: =IF(A11<=12,'Premissas'!$B$24,'Premissas'!$B$25) -> 37000 | W11: =ROUND(G11+Q11,2) -> 138750 | X11: =ROUND(I11+Q11,2) -> 130050 | Y11: =ROUND(L11+R11,2) -> 72796.7 | Z11: =ROUND(SUM(M11:P11)+SUM(S11:V11),2) -> 115909 | AA11: =ROUND(Y11-Z11,2) -> -43112.3 | AB11: =ROUND(AB10+AA11,2) -> -367127.6 | AC11: =ROUND(X11-J11-SUM(M11:P11)-S11-T11-ROUND(Q11*'Premissas'!$B$18,2)-V11,2) -> 36.05 | AD11: =ROUND(SUM($K$5:K11)-SUM($L$5:L11)+SUM($Q$5:Q11)-SUM($R$5:R11),2) -> 101695.05 | AE11: =MAX(0,AB11)*'Premissas'!$B$28 -> 0 | AF11: =IF(AB11>=0,A11,999) -> 999 | AG11: =IF(AE11>=Resumo!$E$6,A11,999) -> 999 | AH11: =AB11+Capital!$A$5 -> -267127.6 | AI11: =AB11+Capital!$A$6 -> -217127.6 | AJ11: =AB11+Capital!$A$7 -> -167127.6
A12: 8 | B12: 1000 | C12: =ROUNDUP(B12/'Premissas'!$B$14,0) -> 50000 | D12: 1 | E12: =D12*'Premissas'!$B$16 -> 80 | F12: =ROUND(B12*'Premissas'!$B$5,2) -> 29000 | G12: =ROUND(F12*'Premissas'!$B$6,2) -> 145000 | H12: =ROUND(G12*'Premissas'!$B$7,2) -> 11600 | I12: =ROUND(G12-H12,2) -> 133400 | J12: =ROUND(I12*'Premissas'!$B$8+B12*(1-'Premissas'!$B$7)*'Premissas'!$B$9*'Premissas'!$B$6,2) -> 17806.6 | K12: =ROUND(I12-J12,2) -> 115593.4 | L12: =IF(A12>'Premissas'!$B$20,INDEX($K$5:$K$28,MAX(1,A12-'Premissas'!$B$20)),0) -> 86695.05 | M12: =ROUND(I12*'Premissas'!$B$10,2) -> 20010 | N12: =ROUND(I12*'Premissas'!$B$11,2) -> 4002 | O12: =ROUND(B12*'Premissas'!$B$12*'Premissas'!$B$6,2) -> 50000 | P12: =ROUND(B12*'Premissas'!$B$13*'Premissas'!$B$6,2) -> 5000 | Q12: =ROUND(D12*'Premissas'!$B$15,2) -> 30000 | R12: =ROUND(Q12*'Premissas'!$B$19+Q11*(1-'Premissas'!$B$19),2) -> 30000 | S12: =ROUND(E12*'Premissas'!$B$17,2) -> 14400 | T12: =ROUND(Q12*'Premissas'!$B$10,2) -> 4500 | U12: =ROUND(R12*'Premissas'!$B$18,2) -> 1500 | V12: =IF(A12<=12,'Premissas'!$B$24,'Premissas'!$B$25) -> 37000 | W12: =ROUND(G12+Q12,2) -> 175000 | X12: =ROUND(I12+Q12,2) -> 163400 | Y12: =ROUND(L12+R12,2) -> 116695.05 | Z12: =ROUND(SUM(M12:P12)+SUM(S12:V12),2) -> 136412 | AA12: =ROUND(Y12-Z12,2) -> -19716.95 | AB12: =ROUND(AB11+AA12,2) -> -386844.55 | AC12: =ROUND(X12-J12-SUM(M12:P12)-S12-T12-ROUND(Q12*'Premissas'!$B$18,2)-V12,2) -> 9181.4 | AD12: =ROUND(SUM($K$5:K12)-SUM($L$5:L12)+SUM($Q$5:Q12)-SUM($R$5:R12),2) -> 130593.4 | AE12: =MAX(0,AB12)*'Premissas'!$B$28 -> 0 | AF12: =IF(AB12>=0,A12,999) -> 999 | AG12: =IF(AE12>=Resumo!$E$6,A12,999) -> 999 | AH12: =AB12+Capital!$A$5 -> -286844.55 | AI12: =AB12+Capital!$A$6 -> -236844.55 | AJ12: =AB12+Capital!$A$7 -> -186844.55
A13: 9 | B13: 1250 | C13: =ROUNDUP(B13/'Premissas'!$B$14,0) -> 62500 | D13: 1 | E13: =D13*'Premissas'!$B$16 -> 80 | F13: =ROUND(B13*'Premissas'!$B$5,2) -> 36250 | G13: =ROUND(F13*'Premissas'!$B$6,2) -> 181250 | H13: =ROUND(G13*'Premissas'!$B$7,2) -> 14500 | I13: =ROUND(G13-H13,2) -> 166750 | J13: =ROUND(I13*'Premissas'!$B$8+B13*(1-'Premissas'!$B$7)*'Premissas'!$B$9*'Premissas'!$B$6,2) -> 22258.25 | K13: =ROUND(I13-J13,2) -> 144491.75 | L13: =IF(A13>'Premissas'!$B$20,INDEX($K$5:$K$28,MAX(1,A13-'Premissas'!$B$20)),0) -> 115593.4 | M13: =ROUND(I13*'Premissas'!$B$10,2) -> 25012.5 | N13: =ROUND(I13*'Premissas'!$B$11,2) -> 5002.5 | O13: =ROUND(B13*'Premissas'!$B$12*'Premissas'!$B$6,2) -> 62500 | P13: =ROUND(B13*'Premissas'!$B$13*'Premissas'!$B$6,2) -> 6250 | Q13: =ROUND(D13*'Premissas'!$B$15,2) -> 30000 | R13: =ROUND(Q13*'Premissas'!$B$19+Q12*(1-'Premissas'!$B$19),2) -> 30000 | S13: =ROUND(E13*'Premissas'!$B$17,2) -> 14400 | T13: =ROUND(Q13*'Premissas'!$B$10,2) -> 4500 | U13: =ROUND(R13*'Premissas'!$B$18,2) -> 1500 | V13: =IF(A13<=12,'Premissas'!$B$24,'Premissas'!$B$25) -> 37000 | W13: =ROUND(G13+Q13,2) -> 211250 | X13: =ROUND(I13+Q13,2) -> 196750 | Y13: =ROUND(L13+R13,2) -> 145593.4 | Z13: =ROUND(SUM(M13:P13)+SUM(S13:V13),2) -> 156165 | AA13: =ROUND(Y13-Z13,2) -> -10571.6 | AB13: =ROUND(AB12+AA13,2) -> -397416.15 | AC13: =ROUND(X13-J13-SUM(M13:P13)-S13-T13-ROUND(Q13*'Premissas'!$B$18,2)-V13,2) -> 18326.75 | AD13: =ROUND(SUM($K$5:K13)-SUM($L$5:L13)+SUM($Q$5:Q13)-SUM($R$5:R13),2) -> 159491.75 | AE13: =MAX(0,AB13)*'Premissas'!$B$28 -> 0 | AF13: =IF(AB13>=0,A13,999) -> 999 | AG13: =IF(AE13>=Resumo!$E$6,A13,999) -> 999 | AH13: =AB13+Capital!$A$5 -> -297416.15 | AI13: =AB13+Capital!$A$6 -> -247416.15 | AJ13: =AB13+Capital!$A$7 -> -197416.15
A14: 10 | B14: 1500 | C14: =ROUNDUP(B14/'Premissas'!$B$14,0) -> 75000 | D14: 1 | E14: =D14*'Premissas'!$B$16 -> 80 | F14: =ROUND(B14*'Premissas'!$B$5,2) -> 43500 | G14: =ROUND(F14*'Premissas'!$B$6,2) -> 217500 | H14: =ROUND(G14*'Premissas'!$B$7,2) -> 17400 | I14: =ROUND(G14-H14,2) -> 200100 | J14: =ROUND(I14*'Premissas'!$B$8+B14*(1-'Premissas'!$B$7)*'Premissas'!$B$9*'Premissas'!$B$6,2) -> 26709.9 | K14: =ROUND(I14-J14,2) -> 173390.1 | L14: =IF(A14>'Premissas'!$B$20,INDEX($K$5:$K$28,MAX(1,A14-'Premissas'!$B$20)),0) -> 144491.75 | M14: =ROUND(I14*'Premissas'!$B$10,2) -> 30015 | N14: =ROUND(I14*'Premissas'!$B$11,2) -> 6003 | O14: =ROUND(B14*'Premissas'!$B$12*'Premissas'!$B$6,2) -> 75000 | P14: =ROUND(B14*'Premissas'!$B$13*'Premissas'!$B$6,2) -> 7500 | Q14: =ROUND(D14*'Premissas'!$B$15,2) -> 30000 | R14: =ROUND(Q14*'Premissas'!$B$19+Q13*(1-'Premissas'!$B$19),2) -> 30000 | S14: =ROUND(E14*'Premissas'!$B$17,2) -> 14400 | T14: =ROUND(Q14*'Premissas'!$B$10,2) -> 4500 | U14: =ROUND(R14*'Premissas'!$B$18,2) -> 1500 | V14: =IF(A14<=12,'Premissas'!$B$24,'Premissas'!$B$25) -> 37000 | W14: =ROUND(G14+Q14,2) -> 247500 | X14: =ROUND(I14+Q14,2) -> 230100 | Y14: =ROUND(L14+R14,2) -> 174491.75 | Z14: =ROUND(SUM(M14:P14)+SUM(S14:V14),2) -> 175918 | AA14: =ROUND(Y14-Z14,2) -> -1426.25 | AB14: =ROUND(AB13+AA14,2) -> -398842.4 | AC14: =ROUND(X14-J14-SUM(M14:P14)-S14-T14-ROUND(Q14*'Premissas'!$B$18,2)-V14,2) -> 27472.1 | AD14: =ROUND(SUM($K$5:K14)-SUM($L$5:L14)+SUM($Q$5:Q14)-SUM($R$5:R14),2) -> 188390.1 | AE14: =MAX(0,AB14)*'Premissas'!$B$28 -> 0 | AF14: =IF(AB14>=0,A14,999) -> 999 | AG14: =IF(AE14>=Resumo!$E$6,A14,999) -> 999 | AH14: =AB14+Capital!$A$5 -> -298842.4 | AI14: =AB14+Capital!$A$6 -> -248842.4 | AJ14: =AB14+Capital!$A$7 -> -198842.4
A15: 11 | B15: 1750 | C15: =ROUNDUP(B15/'Premissas'!$B$14,0) -> 87500 | D15: 1 | E15: =D15*'Premissas'!$B$16 -> 80 | F15: =ROUND(B15*'Premissas'!$B$5,2) -> 50750 | G15: =ROUND(F15*'Premissas'!$B$6,2) -> 253750 | H15: =ROUND(G15*'Premissas'!$B$7,2) -> 20300 | I15: =ROUND(G15-H15,2) -> 233450 | J15: =ROUND(I15*'Premissas'!$B$8+B15*(1-'Premissas'!$B$7)*'Premissas'!$B$9*'Premissas'!$B$6,2) -> 31161.55 | K15: =ROUND(I15-J15,2) -> 202288.45 | L15: =IF(A15>'Premissas'!$B$20,INDEX($K$5:$K$28,MAX(1,A15-'Premissas'!$B$20)),0) -> 173390.1 | M15: =ROUND(I15*'Premissas'!$B$10,2) -> 35017.5 | N15: =ROUND(I15*'Premissas'!$B$11,2) -> 7003.5 | O15: =ROUND(B15*'Premissas'!$B$12*'Premissas'!$B$6,2) -> 87500 | P15: =ROUND(B15*'Premissas'!$B$13*'Premissas'!$B$6,2) -> 8750 | Q15: =ROUND(D15*'Premissas'!$B$15,2) -> 30000 | R15: =ROUND(Q15*'Premissas'!$B$19+Q14*(1-'Premissas'!$B$19),2) -> 30000 | S15: =ROUND(E15*'Premissas'!$B$17,2) -> 14400 | T15: =ROUND(Q15*'Premissas'!$B$10,2) -> 4500 | U15: =ROUND(R15*'Premissas'!$B$18,2) -> 1500 | V15: =IF(A15<=12,'Premissas'!$B$24,'Premissas'!$B$25) -> 37000 | W15: =ROUND(G15+Q15,2) -> 283750 | X15: =ROUND(I15+Q15,2) -> 263450 | Y15: =ROUND(L15+R15,2) -> 203390.1 | Z15: =ROUND(SUM(M15:P15)+SUM(S15:V15),2) -> 195671 | AA15: =ROUND(Y15-Z15,2) -> 7719.1 | AB15: =ROUND(AB14+AA15,2) -> -391123.3 | AC15: =ROUND(X15-J15-SUM(M15:P15)-S15-T15-ROUND(Q15*'Premissas'!$B$18,2)-V15,2) -> 36617.45 | AD15: =ROUND(SUM($K$5:K15)-SUM($L$5:L15)+SUM($Q$5:Q15)-SUM($R$5:R15),2) -> 217288.45 | AE15: =MAX(0,AB15)*'Premissas'!$B$28 -> 0 | AF15: =IF(AB15>=0,A15,999) -> 999 | AG15: =IF(AE15>=Resumo!$E$6,A15,999) -> 999 | AH15: =AB15+Capital!$A$5 -> -291123.3 | AI15: =AB15+Capital!$A$6 -> -241123.3 | AJ15: =AB15+Capital!$A$7 -> -191123.3
A16: 12 | B16: 2000 | C16: =ROUNDUP(B16/'Premissas'!$B$14,0) -> 100000 | D16: 1 | E16: =D16*'Premissas'!$B$16 -> 80 | F16: =ROUND(B16*'Premissas'!$B$5,2) -> 58000 | G16: =ROUND(F16*'Premissas'!$B$6,2) -> 290000 | H16: =ROUND(G16*'Premissas'!$B$7,2) -> 23200 | I16: =ROUND(G16-H16,2) -> 266800 | J16: =ROUND(I16*'Premissas'!$B$8+B16*(1-'Premissas'!$B$7)*'Premissas'!$B$9*'Premissas'!$B$6,2) -> 35613.2 | K16: =ROUND(I16-J16,2) -> 231186.8 | L16: =IF(A16>'Premissas'!$B$20,INDEX($K$5:$K$28,MAX(1,A16-'Premissas'!$B$20)),0) -> 202288.45 | M16: =ROUND(I16*'Premissas'!$B$10,2) -> 40020 | N16: =ROUND(I16*'Premissas'!$B$11,2) -> 8004 | O16: =ROUND(B16*'Premissas'!$B$12*'Premissas'!$B$6,2) -> 100000 | P16: =ROUND(B16*'Premissas'!$B$13*'Premissas'!$B$6,2) -> 10000 | Q16: =ROUND(D16*'Premissas'!$B$15,2) -> 30000 | R16: =ROUND(Q16*'Premissas'!$B$19+Q15*(1-'Premissas'!$B$19),2) -> 30000 | S16: =ROUND(E16*'Premissas'!$B$17,2) -> 14400 | T16: =ROUND(Q16*'Premissas'!$B$10,2) -> 4500 | U16: =ROUND(R16*'Premissas'!$B$18,2) -> 1500 | V16: =IF(A16<=12,'Premissas'!$B$24,'Premissas'!$B$25) -> 37000 | W16: =ROUND(G16+Q16,2) -> 320000 | X16: =ROUND(I16+Q16,2) -> 296800 | Y16: =ROUND(L16+R16,2) -> 232288.45 | Z16: =ROUND(SUM(M16:P16)+SUM(S16:V16),2) -> 215424 | AA16: =ROUND(Y16-Z16,2) -> 16864.45 | AB16: =ROUND(AB15+AA16,2) -> -374258.85 | AC16: =ROUND(X16-J16-SUM(M16:P16)-S16-T16-ROUND(Q16*'Premissas'!$B$18,2)-V16,2) -> 45762.8 | AD16: =ROUND(SUM($K$5:K16)-SUM($L$5:L16)+SUM($Q$5:Q16)-SUM($R$5:R16),2) -> 246186.8 | AE16: =MAX(0,AB16)*'Premissas'!$B$28 -> 0 | AF16: =IF(AB16>=0,A16,999) -> 999 | AG16: =IF(AE16>=Resumo!$E$6,A16,999) -> 999 | AH16: =AB16+Capital!$A$5 -> -274258.85 | AI16: =AB16+Capital!$A$6 -> -224258.85 | AJ16: =AB16+Capital!$A$7 -> -174258.85
A17: 13 | B17: 2200 | C17: =ROUNDUP(B17/'Premissas'!$B$14,0) -> 110000 | D17: 2 | E17: =D17*'Premissas'!$B$16 -> 160 | F17: =ROUND(B17*'Premissas'!$B$5,2) -> 63800 | G17: =ROUND(F17*'Premissas'!$B$6,2) -> 319000 | H17: =ROUND(G17*'Premissas'!$B$7,2) -> 25520 | I17: =ROUND(G17-H17,2) -> 293480 | J17: =ROUND(I17*'Premissas'!$B$8+B17*(1-'Premissas'!$B$7)*'Premissas'!$B$9*'Premissas'!$B$6,2) -> 39174.52 | K17: =ROUND(I17-J17,2) -> 254305.48 | L17: =IF(A17>'Premissas'!$B$20,INDEX($K$5:$K$28,MAX(1,A17-'Premissas'!$B$20)),0) -> 231186.8 | M17: =ROUND(I17*'Premissas'!$B$10,2) -> 44022 | N17: =ROUND(I17*'Premissas'!$B$11,2) -> 8804.4 | O17: =ROUND(B17*'Premissas'!$B$12*'Premissas'!$B$6,2) -> 110000 | P17: =ROUND(B17*'Premissas'!$B$13*'Premissas'!$B$6,2) -> 11000 | Q17: =ROUND(D17*'Premissas'!$B$15,2) -> 60000 | R17: =ROUND(Q17*'Premissas'!$B$19+Q16*(1-'Premissas'!$B$19),2) -> 45000 | S17: =ROUND(E17*'Premissas'!$B$17,2) -> 28800 | T17: =ROUND(Q17*'Premissas'!$B$10,2) -> 9000 | U17: =ROUND(R17*'Premissas'!$B$18,2) -> 2250 | V17: =IF(A17<=12,'Premissas'!$B$24,'Premissas'!$B$25) -> 42000 | W17: =ROUND(G17+Q17,2) -> 379000 | X17: =ROUND(I17+Q17,2) -> 353480 | Y17: =ROUND(L17+R17,2) -> 276186.8 | Z17: =ROUND(SUM(M17:P17)+SUM(S17:V17),2) -> 255876.4 | AA17: =ROUND(Y17-Z17,2) -> 20310.4 | AB17: =ROUND(AB16+AA17,2) -> -353948.45 | AC17: =ROUND(X17-J17-SUM(M17:P17)-S17-T17-ROUND(Q17*'Premissas'!$B$18,2)-V17,2) -> 57679.08 | AD17: =ROUND(SUM($K$5:K17)-SUM($L$5:L17)+SUM($Q$5:Q17)-SUM($R$5:R17),2) -> 284305.48 | AE17: =MAX(0,AB17)*'Premissas'!$B$28 -> 0 | AF17: =IF(AB17>=0,A17,999) -> 999 | AG17: =IF(AE17>=Resumo!$E$6,A17,999) -> 999 | AH17: =AB17+Capital!$A$5 -> -253948.45 | AI17: =AB17+Capital!$A$6 -> -203948.45 | AJ17: =AB17+Capital!$A$7 -> -153948.45
... A28: 24 | B28: 3000 | C28: =ROUNDUP(B28/'Premissas'!$B$14,0) -> 150000 | D28: 2 | E28: =D28*'Premissas'!$B$16 -> 160 | F28: =ROUND(B28*'Premissas'!$B$5,2) -> 87000 | G28: =ROUND(F28*'Premissas'!$B$6,2) -> 435000 | H28: =ROUND(G28*'Premissas'!$B$7,2) -> 34800 | I28: =ROUND(G28-H28,2) -> 400200 | J28: =ROUND(I28*'Premissas'!$B$8+B28*(1-'Premissas'!$B$7)*'Premissas'!$B$9*'Premissas'!$B$6,2) -> 53419.8 | K28: =ROUND(I28-J28,2) -> 346780.2 | L28: =IF(A28>'Premissas'!$B$20,INDEX($K$5:$K$28,MAX(1,A28-'Premissas'!$B$20)),0) -> 346780.2 | M28: =ROUND(I28*'Premissas'!$B$10,2) -> 60030 | N28: =ROUND(I28*'Premissas'!$B$11,2) -> 12006 | O28: =ROUND(B28*'Premissas'!$B$12*'Premissas'!$B$6,2) -> 150000 | P28: =ROUND(B28*'Premissas'!$B$13*'Premissas'!$B$6,2) -> 15000 | Q28: =ROUND(D28*'Premissas'!$B$15,2) -> 60000 | R28: =ROUND(Q28*'Premissas'!$B$19+Q27*(1-'Premissas'!$B$19),2) -> 60000 | S28: =ROUND(E28*'Premissas'!$B$17,2) -> 28800 | T28: =ROUND(Q28*'Premissas'!$B$10,2) -> 9000 | U28: =ROUND(R28*'Premissas'!$B$18,2) -> 3000 | V28: =IF(A28<=12,'Premissas'!$B$24,'Premissas'!$B$25) -> 42000 | W28: =ROUND(G28+Q28,2) -> 495000 | X28: =ROUND(I28+Q28,2) -> 460200 | Y28: =ROUND(L28+R28,2) -> 406780.2 | Z28: =ROUND(SUM(M28:P28)+SUM(S28:V28),2) -> 319836 | AA28: =ROUND(Y28-Z28,2) -> 86944.2 | AB28: =ROUND(AB27+AA28,2) -> 466065.35 | AC28: =ROUND(X28-J28-SUM(M28:P28)-S28-T28-ROUND(Q28*'Premissas'!$B$18,2)-V28,2) -> 86944.2 | AD28: =ROUND(SUM($K$5:K28)-SUM($L$5:L28)+SUM($Q$5:Q28)-SUM($R$5:R28),2) -> 376780.2 | AE28: =MAX(0,AB28)*'Premissas'!$B$28 -> 233032.67 | AF28: =IF(AB28>=0,A28,999) -> 24 | AG28: =IF(AE28>=Resumo!$E$6,A28,999) -> 999 | AH28: =AB28+Capital!$A$5 -> 566065.35 | AI28: =AB28+Capital!$A$6 -> 616065.35 | AJ28: =AB28+Capital!$A$7 -> 666065.35

Sheet Escala24
A1: Escala24 | fluxo mensal em BRL, salvo indicação
A2: Agenda editável em azul. Cenário hipotético; não previsão. | M0 separado: -R$100 mil nas premissas. Acumulado exclui aportes/distribuição.
A4: Mês | B4: Pedidos aprovados | C4: Visitas qualificadas | D4: Mapas faturados | E4: Horas diretas TI | F4: Loja bruta USD | G4: Loja bruta BRL | H4: Estornos BRL | I4: Loja após estornos BRL | J4: Taxa plataforma BRL | K4: Liquidação gerada BRL | L4: Loja recebida BRL | M4: Tributos loja BRL | N4: Reserva meios/FX BRL | O4: Aquisição / mídia BRL | P4: Suporte loja BRL | Q4: Fatura TI BRL | R4: Recebimentos TI BRL | S4: Entrega TI BRL | T4: Tributos TI BRL | U4: Comercial TI caixa BRL | V4: Fixo BRL | W4: Vendas brutas BRL | X4: Receita após estornos BRL | Y4: Recebimentos BRL | Z4: Saídas caixa BRL | AA4: Fluxo líquido BRL | AB4: Acumulado sem aporte BRL | AC4: Resultado competência BRL | AD4: A receber BRL | AE4: 50% excedente positivo BRL | AF4: Mês elegível payback projeto | AG4: Mês elegível Dani hipotético | AH4: Saldo com 100k | AI4: Saldo com 150k | AJ4: Saldo com 200k
A5: 1 | B5: 0 | C5: =ROUNDUP(B5/'Premissas'!$B$14,0) -> 0 | D5: 0 | E5: =D5*'Premissas'!$B$16 -> 0 | F5: =ROUND(B5*'Premissas'!$B$5,2) -> 0 | G5: =ROUND(F5*'Premissas'!$B$6,2) -> 0 | H5: =ROUND(G5*'Premissas'!$B$7,2) -> 0 | I5: =ROUND(G5-H5,2) -> 0 | J5: =ROUND(I5*'Premissas'!$B$8+B5*(1-'Premissas'!$B$7)*'Premissas'!$B$9*'Premissas'!$B$6,2) -> 0 | K5: =ROUND(I5-J5,2) -> 0 | L5: =IF(A5>'Premissas'!$B$20,INDEX($K$5:$K$28,MAX(1,A5-'Premissas'!$B$20)),0) -> 0 | M5: =ROUND(I5*'Premissas'!$B$10,2) -> 0 | N5: =ROUND(I5*'Premissas'!$B$11,2) -> 0 | O5: =ROUND(B5*'Premissas'!$B$12*'Premissas'!$B$6,2) -> 0 | P5: =ROUND(B5*'Premissas'!$B$13*'Premissas'!$B$6,2) -> 0 | Q5: =ROUND(D5*'Premissas'!$B$15,2) -> 0 | R5: =ROUND(Q5*'Premissas'!$B$19+0*(1-'Premissas'!$B$19),2) -> 0 | S5: =ROUND(E5*'Premissas'!$B$17,2) -> 0 | T5: =ROUND(Q5*'Premissas'!$B$10,2) -> 0 | U5: =ROUND(R5*'Premissas'!$B$18,2) -> 0 | V5: =IF(A5<=12,'Premissas'!$B$24,'Premissas'!$B$25) -> 37000 | W5: =ROUND(G5+Q5,2) -> 0 | X5: =ROUND(I5+Q5,2) -> 0 | Y5: =ROUND(L5+R5,2) -> 0 | Z5: =ROUND(SUM(M5:P5)+SUM(S5:V5),2) -> 37000 | AA5: =ROUND(Y5-Z5,2) -> -37000 | AB5: =ROUND(-'Premissas'!$B$23+AA5,2) -> -137000 | AC5: =ROUND(X5-J5-SUM(M5:P5)-S5-T5-ROUND(Q5*'Premissas'!$B$18,2)-V5,2) -> -37000 | AD5: =ROUND(SUM($K$5:K5)-SUM($L$5:L5)+SUM($Q$5:Q5)-SUM($R$5:R5),2) -> 0 | AE5: =MAX(0,AB5)*'Premissas'!$B$28 -> 0 | AF5: =IF(AB5>=0,A5,999) -> 999 | AG5: =IF(AE5>=Resumo!$E$7,A5,999) -> 999 | AH5: =AB5+Capital!$A$5 -> -37000 | AI5: =AB5+Capital!$A$6 -> 13000 | AJ5: =AB5+Capital!$A$7 -> 63000
